Workbook
Name UPDATE: '[1]Data Sheet'!$E$1
Name UPDATE: '[2]Data Sheet'!$E$1
Name UPDATE: '[2]Data Sheet'!$E$1
Name UPDATE: '[1]Data Sheet'!$E$1
Name UPDATE: 'Data Sheet'!$E$1

Sheet Intrinsic Values
A1: Intrinsic Value Range | F1: Remember! Give importance to a stock's valuations / fair value only "after" you have answered in "Yes" to these two questions - (1) Is this business simple to be understood? and (2) Can I understand this business? Don't try to quantify everything. In stock research, the less non-mathematical you are, the more simple, sensible, and useful will be your analysis and results. Great analysis is generally "back-of-the-envelope". Also, your calculated "fair value" will be proven wrong in the future, so don't invest your savings just because you fall in love with it. Don't look for perfection. It is overrated. Focus on decisions, not outcomes. Look for disconfirming evidence.
A2: ='Data Sheet'!B1 -> LIFE INSURANCE CORPORATION OF INDIA
B3: Lower | C3: Higher
A4: Dhandho | B4: =IFERROR('Dhandho model'!D17,0) -> 1037616.7 | C4: =IFERROR('Dhandho model'!M17,0) -> 3402802.4
A5: Ben Graham | B5: =IFERROR('Ben Graham '!B10,0) -> 302374.96 | C5: =IFERROR('Ben Graham '!E10,0) -> 329865.14
A6: DCF | B6: ='DCF '!G29 -> 1181485.9 | C6: ='DCF '!B29 -> 2323976.8
A7: Expected Return | B7: ='Expected Returns Model'!B28 -> 1207843.3 | C7: ='Expected Returns Model'!B18 -> 7016238.2
A8: FBTA - TVM - CMMM | B8: ='FBTA - TMV - CMMM'!E18 -> 1249670.7 | C8: ='FBTA - TMV - CMMM'!P21 -> 5068662.8
A9: FCFE | B9: ='FCFE(L)'!M14 -> 2760861.2 | C9: ='FCFE (H) '!M14 -> 2944339.5
A10: MCAP | B10: =AVERAGE(B4:B9) -> 1289975.5 | C10: =AVERAGE(C4:C9) -> 3514314.1
A11: Average MCAP | B11: =AVERAGE(B10:C10) -> 2402144.8
A12: Price | B12: =B10/'Data Sheet'!B6 -> 2039.4876 | C12: =C10/'Data Sheet'!B6 -> 5556.2299
A13: Best Price to Accumulate | B13: =AVERAGE(B12:C12) -> 3797.8588
A14: Current Market Cap. | B14: ='Data Sheet'!B9 -> 592367.66
A15: Premium or Discount | B15: =(B14/B11)-1 -> -0.75340052
A17: Explanation: Considering the above range, we can say that LICI IV range is between Rs. 12,55,024 crore to Rs. 1,18,65,210 crore. It's a big range, but that's fine (who is looking for precision?). Now, if the current market cap is within this IV range, it makes the stock reasonably/attractively priced. If the current market cap is higher then the higher value of the range, it makes it overpriced. But remember, these are just numbers!

Sheet FCFE (H) 
A1: S.No | B1: Year | C1: EPS | D1: Growth Rate | E1: Beta | F1: CAPM | G1: (Capex-Dep)/Shares outstanding | H1: WC/shares = NCAVPS | I1: Change in WC | J1: (Change in WC)(1- Debt Ratio) | K1: (Capex - Dep)(1- DR) | L1: FCFE | M1: PV of FCFE
A2: 1 | B2: 2025 | C2: ='Profit and loss Detailed-BRT '!H26 -> 76.395779 | D2: ='Profit and loss Detailed-BRT '!I26 -> 0.1031197 | E2: =$C$18 -> 1.05 | F2: =$F$14+E2*($F$15-$F$14) -> 0.1026627 | G2: =(F17-F18)/C20 -> 1.1301032 | H2: =F19/C20 -> -8210.0559
A3: 2 | B3: 2026 | C3: =C2*(1+D2) -> 84.273689 | D3: =D2-$C$16 -> 0.093119705 | E3: =$C$18 -> 1.05 | F3: =$F$14+E3*($F$15-$F$14) -> 0.1026627 | G3: =G2*(1+D3) -> 1.2353381 | H3: =H2*(1+D3) -> -8974.5739 | I3: =(H3-H2) -> -764.51798 | J3: =I3*(1-$F$21) -> -764.51203 | K3: =G3*(1-$F$21) -> 1.2353284 | L3: =(C3-K3-J3) -> 847.55039 | M3: =(L3)/(1+F3)^A2 -> 768.63976
A4: 3 | B4: 2027 | C4: =C3*(1+D3) -> 92.12123 | D4: =D3-$C$16 -> 0.083119705 | E4: =$C$18 -> 1.05 | F4: =$F$14+E4*($F$15-$F$14) -> 0.1026627 | G4: =G3*(1+D4) -> 1.338019 | H4: =H3*(1+D4) -> -9720.5378 | I4: =(H4-H3) -> -745.96393 | J4: =I4*(1-$F$21) -> -745.95812 | K4: =G4*(1-$F$21) -> 1.3380086 | L4: =(C4-K4-J4) -> 836.74135 | M4: =(L4)/(1+F4)^A3 -> 688.18605
A5: 4 | B5: 2028 | C5: =C4*(1+D4) -> 99.778319 | D5: =D4-$C$16 -> 0.073119705 | E5: =$C$18 -> 1.05 | F5: =$F$14+E5*($F$15-$F$14) -> 0.1026627 | G5: =G4*(1+D5) -> 1.4358545 | H5: =H4*(1+D5) -> -10431.301 | I5: =(H5-H4) -> -710.76285 | J5: =I5*(1-$F$21) -> -710.75732 | K5: =G5*(1-$F$21) -> 1.4358434 | L5: =(C5-K5-J5) -> 809.0998 | M5: =(L5)/(1+F5)^A4 -> 603.49551
A6: 5 | B6: 2029 | C6: =C5*(1+D5) -> 107.07408 | D6: =D5-$C$16 -> 0.063119705 | E6: =$C$18 -> 1.05 | F6: =$F$14+E6*($F$15-$F$14) -> 0.1026627 | G6: =G5*(1+D6) -> 1.5264853 | H6: =H5*(1+D6) -> -11089.721 | I6: =(H6-H5) -> -658.42062 | J6: =I6*(1-$F$21) -> -658.41549 | K6: =G6*(1-$F$21) -> 1.5264734 | L6: =(C6-K6-J6) -> 763.9631 | M6: =(L6)/(1+F6)^A5 -> 516.77518
A7: 6 | B7: 2030 | C7: =C6*(1+D6) -> 113.83256 | D7: =D6-$C$16 -> 0.053119705 | E7: =$C$18 -> 1.05 | F7: =$F$14+E7*($F$15-$F$14) -> 0.1026627 | G7: =G6*(1+D7) -> 1.6075717 | H7: =H6*(1+D7) -> -11678.804 | I7: =(H7-H6) -> -589.08272 | J7: =I7*(1-$F$21) -> -589.07813 | K7: =G7*(1-$F$21) -> 1.6075592 | L7: =(C7-K7-J7) -> 701.30314 | M7: =(L7)/(1+F7)^A6 -> 430.22176
A8: 7 | B8: 2031 | C8: =C7*(1+D7) -> 119.87932 | D8: =D7-$C$16 -> 0.043119705 | E8: =$C$18 -> 1.05 | F8: =$F$14+E8*($F$15-$F$14) -> 0.1026627 | G8: =G7*(1+D8) -> 1.6768897 | H8: =H7*(1+D8) -> -12182.391 | I8: =(H8-H7) -> -503.58658 | J8: =I8*(1-$F$21) -> -503.58266 | K8: =G8*(1-$F$21) -> 1.6768767 | L8: =(C8-K8-J8) -> 621.7851 | M8: =(L8)/(1+F8)^A7 -> 345.9268
A9: 8 | B9: 2032 | C9: =C8*(1+D8) -> 125.04848 | D9: =D8-$C$16 -> 0.033119705 | E9: =$C$18 -> 1.05 | F9: =$F$14+E9*($F$15-$F$14) -> 0.1026627 | G9: =G8*(1+D9) -> 1.7324278 | H9: =H8*(1+D9) -> -12585.868 | I9: =(H9-H8) -> -403.47718 | J9: =I9*(1-$F$21) -> -403.47404 | K9: =G9*(1-$F$21) -> 1.7324143 | L9: =(C9-K9-J9) -> 526.7901 | M9: =(L9)/(1+F9)^A8 -> 265.79012
A10: 9 | B10: 2033 | C10: =C9*(1+D9) -> 129.19005 | D10: =D9-$C$16 -> 0.023119705 | E10: =$C$18 -> 1.05 | F10: =$F$14+E10*($F$15-$F$14) -> 0.1026627 | G10: =G9*(1+D10) -> 1.772481 | H10: =H9*(1+D10) -> -12876.849 | I10: =(H10-H9) -> -290.98154 | J10: =I10*(1-$F$21) -> -290.97928 | K10: =G10*(1-$F$21) -> 1.7724672 | L10: =(C10-K10-J10) -> 418.39686 | M10: =(L10)/(1+F10)^A9 -> 191.44629
A11: 10 | B11: 2034 | C11: =C10*(1+D10) -> 132.17688 | D11: =D10-$C$16 -> 0.013119705 | E11: =$C$18 -> 1.05 | F11: =$F$14+E11*($F$15-$F$14) -> 0.1026627 | G11: =G10*(1+D11) -> 1.7957355 | H11: =H10*(1+D11) -> -13045.79 | I11: =(H11-H10) -> -168.94046 | J11: =I11*(1-$F$21) -> -168.93914 | K11: =G11*(1-$F$21) -> 1.7957215 | L11: =(C11-K11-J11) -> 299.3203 | M11: =(L11)/(1+F11)^A10 -> 124.2087
A12: 11 | B12: 2035 | C12: =C11*(1+D11) -> 133.911 | D12: =D11-$C$16 -> 0.0031197046 | E12: =$C$18 -> 1.05 | F12: =$F$14+E12*($F$15-$F$14) -> 0.1026627 | G12: =G11*(1+D12) -> 1.8013376 | H12: =H11*(1+D12) -> -13086.489 | I12: =(H12-H11) -> -40.69901 | J12: =I12*(1-$F$21) -> -40.698694 | K12: =G12*(1-$F$21) -> 1.8013236 | L12: =(C12-K12-J12) -> 172.80837 | M12: =F23 -> 720.39376
L13: =SUM(L3:L11) -> 5824.9501 | M13: =SUM(M3:M12) -> 4655.0839
B14: Growth Rate till 2025 | C14: ='Profit and loss Detailed-BRT '!I26 -> 0.1031197 | E14: Risk Free Rate (Rf) | F14: 0.055 | L14: MCAP | M14: =M13*C20 -> 2944339.5
E15: Market Return (Rm) | F15: =(25149/8780)^(1/11)-1 -> 0.10039305
B16: Growth every year decline | C16: 0.01 | F16: (Per Share)
E17: Capex | F17: ='Cash Flow'!K12 -> 714.79 | K17: Price in 2035 | L17: =F22+L13 -> 7560.9676
B18: Beta for high growth period | C18: 1.05 | E18: Dep | F18: ='Profit and loss Detailed-BRT '!H16 -> 0
E19: Working Capital | F19: ='Balance Sheet'!K16 -> -5192858.5
B20: No. Of Shares | C20: ='Basic Sheet'!D5 -> 632.49977
E21: Debt Ratio | F21: ='Balance Sheet'!K25 -> 7.7814045e-06
B22: Terminal Growth Rate | C22: 0.05 | E22: Terminal Value | F22: =L12/(F12-D12) -> 1736.0175 | G22: PV
E23: PV of Terminal Value | F23: =(F22)/((1+F10)*(1+F9)*(1+F8)*(1+F7)*(1+F6)^5) -> 720.39376 | H23: CAPM = Rf+B(Rm-Rf)
F24: =F22/(1+F12)^9 -> 720.39376 | H24: FCFE = EPS - (Capex-Dep)*(1-DR) - (Change in WC)*(1-DR)
B25: CMP | C25: ='Data Sheet'!B8 -> 936.55
H28: Free Cash Flow Of Firm

Sheet FCFE(L)
A1: S.No | B1: Year | C1: EPS | D1: Growth Rate | E1: Beta | F1: CAPM | G1: (Capex-Dep)/Shares outstanding | H1: WC/shares | I1: Change in WC | J1: (Change in WC)(1- Debt Ratio) | K1: (Capex - Dep)(1- DR) | L1: FCFE | M1: PV of FCFE
A2: 1 | B2: 2025 | C2: ='FCFE (H) '!C2 -> 76.395779 | D2: =C14 -> 0.1031197 | E2: =$C$18 -> 1.05 | F2: =$F$14+E2*($F$15-$F$14) -> 0.1026627 | G2: =(F17-F18)/C20 -> 1.1301032 | H2: =F19/C20 -> -8210.0559
A3: 2 | B3: 2026 | C3: =C2*(1+D2) -> 84.273689 | D3: =D2-$C$16 -> 0.092807734 | E3: =$C$18 -> 1.05 | F3: =$F$14+E3*($F$15-$F$14) -> 0.1026627 | G3: =G2*(1+D3) -> 1.2349855 | H3: =H2*(1+D3) -> -8972.0126 | I3: =(H3-H2) -> -761.95668 | J3: =I3*(1-$F$21) -> -761.95076 | K3: =G3*(1-$F$21) -> 1.2349759 | L3: =(C3-K3-J3) -> 844.98947 | M3: =(L3)/(1+F3)^A2 -> 766.31727
A4: 3 | B4: 2027 | C4: =C3*(1+D3) -> 92.094939 | D4: =D3-$C$16 -> 0.082495764 | E4: =$C$18 -> 1.05 | F4: =$F$14+E4*($F$15-$F$14) -> 0.1026627 | G4: =G3*(1+D4) -> 1.3368666 | H4: =H3*(1+D4) -> -9712.1656 | I4: =(H4-H3) -> -740.15303 | J4: =I4*(1-$F$21) -> -740.14727 | K4: =G4*(1-$F$21) -> 1.3368562 | L4: =(C4-K4-J4) -> 830.90535 | M4: =(L4)/(1+F4)^A3 -> 683.38618
A5: 4 | B5: 2028 | C5: =C4*(1+D4) -> 99.692381 | D5: =D4-$C$16 -> 0.072183793 | E5: =$C$18 -> 1.05 | F5: =$F$14+E5*($F$15-$F$14) -> 0.1026627 | G5: =G4*(1+D5) -> 1.4333667 | H5: =H4*(1+D5) -> -10413.227 | I5: =(H5-H4) -> -701.06095 | J5: =I5*(1-$F$21) -> -701.0555 | K5: =G5*(1-$F$21) -> 1.4333555 | L5: =(C5-K5-J5) -> 799.31452 | M5: =(L5)/(1+F5)^A4 -> 596.19682
A6: 5 | B6: 2029 | C6: =C5*(1+D5) -> 106.88856 | D6: =D5-$C$16 -> 0.061871823 | E6: =$C$18 -> 1.05 | F6: =$F$14+E6*($F$15-$F$14) -> 0.1026627 | G6: =G5*(1+D6) -> 1.5220517 | H6: =H5*(1+D6) -> -11057.512 | I6: =(H6-H5) -> -644.28531 | J6: =I6*(1-$F$21) -> -644.2803 | K6: =G6*(1-$F$21) -> 1.5220398 | L6: =(C6-K6-J6) -> 749.64681 | M6: =(L6)/(1+F6)^A5 -> 507.09107
A7: 6 | B7: 2030 | C7: =C6*(1+D6) -> 113.50195 | D7: =D6-$C$16 -> 0.051559852 | E7: =$C$18 -> 1.05 | F7: =$F$14+E7*($F$15-$F$14) -> 0.1026627 | G7: =G6*(1+D7) -> 1.6005284 | H7: =H6*(1+D7) -> -11627.636 | I7: =(H7-H6) -> -570.12368 | J7: =I7*(1-$F$21) -> -570.11924 | K7: =G7*(1-$F$21) -> 1.600516 | L7: =(C7-K7-J7) -> 682.02067 | M7: =(L7)/(1+F7)^A6 -> 418.39272
A8: 7 | B8: 2031 | C8: =C7*(1+D7) -> 119.35409 | D8: =D7-$C$16 -> 0.041247882 | E8: =$C$18 -> 1.05 | F8: =$F$14+E8*($F$15-$F$14) -> 0.1026627 | G8: =G7*(1+D8) -> 1.6665468 | H8: =H7*(1+D8) -> -12107.251 | I8: =(H8-H7) -> -479.61534 | J8: =I8*(1-$F$21) -> -479.61161 | K8: =G8*(1-$F$21) -> 1.6665339 | L8: =(C8-K8-J8) -> 597.29916 | M8: =(L8)/(1+F8)^A7 -> 332.30418
A9: 8 | B9: 2032 | C9: =C8*(1+D8) -> 124.27719 | D9: =D8-$C$16 -> 0.030935911 | E9: =$C$18 -> 1.05 | F9: =$F$14+E9*($F$15-$F$14) -> 0.1026627 | G9: =G8*(1+D9) -> 1.718103 | H9: =H8*(1+D9) -> -12481.8 | I9: =(H9-H8) -> -374.54884 | J9: =I9*(1-$F$21) -> -374.54593 | K9: =G9*(1-$F$21) -> 1.7180896 | L9: =(C9-K9-J9) -> 497.10503 | M9: =(L9)/(1+F9)^A8 -> 250.81262
A10: 9 | B10: 2033 | C10: =C9*(1+D9) -> 128.12182 | D10: =D9-$C$16 -> 0.020623941 | E10: =$C$18 -> 1.05 | F10: =$F$14+E10*($F$15-$F$14) -> 0.1026627 | G10: =G9*(1+D10) -> 1.753537 | H10: =H9*(1+D10) -> -12739.224 | I10: =(H10-H9) -> -257.4239 | J10: =I10*(1-$F$21) -> -257.4219 | K10: =G10*(1-$F$21) -> 1.7535234 | L10: =(C10-K10-J10) -> 383.79019 | M10: =(L10)/(1+F10)^A9 -> 175.61128
A11: 10 | B11: 2034 | C11: =C10*(1+D10) -> 130.7642 | D11: =D10-$C$16 -> 0.01031197 | E11: =$C$18 -> 1.05 | F11: =$F$14+E11*($F$15-$F$14) -> 0.1026627 | G11: =G10*(1+D11) -> 1.7716195 | H11: =H10*(1+D11) -> -12870.59 | I11: =(H11-H10) -> -131.3665 | J11: =I11*(1-$F$21) -> -131.36548 | K11: =G11*(1-$F$21) -> 1.7716057 | L11: =(C11-K11-J11) -> 260.35807 | M11: =(L11)/(1+F11)^A10 -> 108.04058
A12: 11 | B12: 2035 | C12: =C11*(1+D11) -> 132.11263 | D12: =D11-$C$16 -> 0 | E12: =$C$18 -> 1.05 | F12: =$F$14+E12*($F$15-$F$14) -> 0.1026627 | G12: =G11*(1+D12) -> 1.7716195 | H12: =H11*(1+D12) -> -12870.59 | I12: =(H12-H11) -> 0 | J12: =I12*(1-$F$21) -> 0 | K12: =G12*(1-$F$21) -> 1.7716057 | L12: =(C12-K12-J12) -> 130.34103 | M12: =F23 -> 526.84678
L13: =SUM(L3:L11) -> 5645.4293 | M13: =SUM(M3:M12) -> 4364.9995
B14: Growth Rate till 2025 | C14: ='FCFE (H) '!C14 -> 0.1031197 | E14: Risk Free Rate | F14: 0.055 | L14: MCAP | M14: =M13*C20 -> 2760861.2
E15: Market Return | F15: ='FCFE (H) '!F15 -> 0.10039305
B16: Growth every year decline | C16: =(C14-0)/10 -> 0.01031197 | F16: (Per Share)
E17: Capex | F17: ='FCFE (H) '!F17 -> 714.79 | K17: Price in 2035 | L17: =F22+L13 -> 6915.0338
B18: Beta for high growth period | C18: 1.05 | E18: Dep | F18: ='FCFE (H) '!F18 -> 0
E19: Working Capital | F19: ='FCFE (H) '!F19 -> -5192858.5
B20: No. Of Shares | C20: ='Data Sheet'!B6 -> 632.49977
E21: Debt Ratio | F21: ='FCFE (H) '!F21 -> 7.7814045e-06
E22: Terminal Value | F22: =L12/(F12-D12) -> 1269.6046
E23: PV of Terminal Value | F23: =(F22)/((1+F10)*(1+F9)*(1+F8)*(1+F7)*(1+F6)^5) -> 526.84678
B25: CMP | C25: ='Data Sheet'!B8 -> 936.55

Sheet DCF 
A1: Dicounted Cash Flow Valuation
A2: ='Data Sheet'!B1 -> LIFE INSURANCE CORPORATION OF INDIA
A4: Initial Cash Flow (Rs Cr) | B4: ='Cash Flow'!K14 -> 30482.309 | D4: =$B$18*(1+$C$7)^A14 -> 68668.108
D5: =$B$18*(1+$C$7)^A15 -> 76908.281
A6: Years | B6: 1-5 | C6: 6-10 | D6: =$B$18*(1+$C$7)^A16 -> 86137.275 | F6: 1-5 | G6: 6-10
A7: FCF Growth Rate | B7: 0.15 | C7: 0.12 | D7: =$B$18*(1+$C$7)^A17 -> 96473.748 | F7: 0.1 | G7: 0.05
A8: Discount Rate | B8: 0.055 | D8: =$B$18*(1+$C$7)^A18 -> 108050.6
A9: Terminal Growth Rate | B9: 0.02 | C9: 0.01
A11: Net Debt Level (Rs Cr) | B11: ='Balance Sheet'!K6-'Balance Sheet'!K19 -> -69883.67
A13: Year | B13: FCF | C13: Growth | D13: Present Value | F13: Year | G13: FCF | H13: Growth | I13: Present Value
A14: 1 | B14: =B4*(1+C14) -> 35054.655 | C14: =$B$7 -> 0.15 | D14: =B14/((1+$B$8)^A14) -> 33227.161 | F14: 1 | G14: =(B4*H14)+B4 -> 33530.54 | H14: 0.1 | I14: =G14/((1+$B$8)^F14) -> 31782.502
A15: 2 | B15: =B14*(1+C15)^A14 -> 40312.853 | C15: =$B$7 -> 0.15 | D15: =B15/((1+$B$8)^A15) -> 36219.18 | F15: 2 | G15: =(G14*H15)+G14 -> 36883.594 | H15: 0.1 | I15: =G15/((1+$B$8)^F15) -> 33138.154
A16: 3 | B16: =(B15*C16)+B15 -> 46359.781 | C16: =$B$7 -> 0.15 | D16: =B16/((1+$B$8)^A16) -> 39480.623 | F16: 3 | G16: =(G15*H16)+G15 -> 40571.953 | H16: 0.1 | I16: =G16/((1+$B$8)^F16) -> 34551.63
A17: 4 | B17: =(B16*C17)+B16 -> 53313.749 | C17: =$B$7 -> 0.15 | D17: =B17/((1+$B$8)^A17) -> 43035.75 | F17: 4 | G17: =(G16*H17)+G16 -> 44629.148 | H17: 0.1 | I17: =G17/((1+$B$8)^F17) -> 36025.396
A18: 5 | B18: =(B17*C18)+B17 -> 61310.811 | C18: =$B$7 -> 0.15 | D18: =B18/((1+$B$8)^A18) -> 46911.008 | F18: 5 | G18: =(G17*H18)+G17 -> 49092.063 | H18: 0.1 | I18: =G18/((1+$B$8)^F18) -> 37562.024
A19: 6 | B19: =(B18*C19)+B18 -> 68668.108 | C19: =$C$7 -> 0.12 | D19: =B19/((1+$B$8)^A19) -> 49801.259 | F19: 6 | G19: =(G18*H19)+G18 -> 51546.666 | H19: 0.05 | I19: =G19/((1+$B$8)^F19) -> 37384.005
A20: 7 | B20: =(B19*C20)+B19 -> 76908.281 | C20: =$C$7 -> 0.12 | D20: =B20/((1+$B$8)^A20) -> 52869.583 | F20: 7 | G20: =(G19*H20)+G19 -> 54124 | H20: 0.05 | I20: =G20/((1+$B$8)^F20) -> 37206.83
A21: 8 | B21: =(B20*C21)+B20 -> 86137.275 | C21: =$C$7 -> 0.12 | D21: =B21/((1+$B$8)^A21) -> 56126.951 | F21: 8 | G21: =(G20*H21)+G20 -> 56830.2 | H21: 0.05 | I21: =G21/((1+$B$8)^F21) -> 37030.494
A22: 9 | B22: =(B21*C22)+B21 -> 96473.748 | C22: =$C$7 -> 0.12 | D22: =B22/((1+$B$8)^A22) -> 59585.01 | F22: 9 | G22: =(G21*H22)+G21 -> 59671.71 | H22: 0.05 | I22: =G22/((1+$B$8)^F22) -> 36854.994
A23: 10 | B23: =(B22*C23)+B22 -> 108050.6 | C23: =$C$7 -> 0.12 | D23: =B23/((1+$B$8)^A23) -> 63256.124 | F23: 10 | G23: =(G22*H23)+G22 -> 62655.295 | H23: 0.05 | I23: =G23/((1+$B$8)^F23) -> 36680.326
A25: Final Calculations - Higher Value | F25: Final Calculations - Lower Range
A26: Terminal Year | B26: =B23*(1+B9) -> 110211.61 | F26: Terminal Year | G26: =G23*(1+C9) -> 63281.848 | I26: =G18*(1+G7) -> 51546.666 | J26: TV = Terminal Year Value/(K-g)/(1+K)^n
A27: PV of Year 1-10 Cash Flows | B27: =SUM(D14:D23) -> 480512.65 | F27: PV of Year 1-10 Cash Flows | G27: =SUM(I14:I23) -> 358216.35 | I27: =(B4*(1+F7)^5)*(1+G7) -> 51546.666
A28: Terminal Value | B28: =((B26)/($B$8-$B$9))/(1+$B$8)^A23 -> 1843464.2 | C28: =B26/(B8-B9) -> 3148903.1 | F28: Terminal Value | G28: =((G26)/($B$8-$C$9))/(1+$B$8)^F23 -> 823269.53
A29: Total PV of Cash Flows | B29: =B27+B28 -> 2323976.8 | C29: =C28/(1+B8)^A23 -> 1843464.2 | F29: Total PV of Cash Flows | G29: =G27+G28 -> 1181485.9
A30: Current Market Cap (Rs Cr) | B30: ='Basic Sheet'!D6 -> 592367.66 | F30: Current Market Cap (Rs Cr) | G30: =B30 -> 592367.66
A31: MCAP/DCF % | B31: =(B30/B29)-1 -> -0.74510604 | F31: MCAP/DCF % | G31: =(G30/G29)-1 -> -0.49862485
A32: DCF Price | B32: =B29/'Data Sheet'!B6 -> 3674.273 | F32: DCF Price | G32: =G29/'Data Sheet'!B6 -> 1867.9626

Sheet Ben Graham 
A1: Ben Graham Formula (Low Range) | D1: Ben Graham Formula (High Range)
A3: Company Name | B3: LIFE INSURANCE CORPORATION OF INDIA | D3: Company Name | E3: LIFE INSURANCE CORPORATION OF INDIA
A4: Year Ended | B4: 45747 | D4: Year Ended | E4: 45747
A6: Avg 4-Yr Net Profit (Rs Crore) | B6: =AVERAGE('Profit & Loss'!H12:K12) -> 32339.385 | D6: Avg 4-Yr Net Profit (Rs Crore) | E6: =AVERAGE('Profit & Loss'!H12:K12) -> 32339.385
A7: PE Ratio at 0% Growth | B7: 8.5 | D7: PE Ratio at 0% Growth | E7: 8.5
A8: Long-Term Growth Rate | B8: =C8/2 -> 0.42502639 | C8: =('Profit & Loss'!K12/'Profit & Loss'!H12)^(1/4)-1 -> 0.85005278 | D8: Long-Term Growth Rate | E8: =('Profit & Loss'!K12/'Profit & Loss'!H12)^(1/4)-1 -> 0.85005278
A10: Ben Graham Value (Rs Crore) | B10: =B6*(B7+2*B8) -> 302374.96 | D10: Ben Graham Value (Rs Crore) | E10: =E6*(E7+2*E8) -> 329865.14 | F10: =(E6*(E7+2*E8)*5.5)/6.295 -> 288206.24
A11: Ben Graham Price | B11: =B10/'Data Sheet'!B6 -> 478.06335 | D11: Ben Graham Price | E11: =E10/'Data Sheet'!B6 -> 521.5261 | F11: =F10/'Data Sheet'!B6 -> 455.6622
A12: Current Market Cap (Rs Crore) | B12: ='Data Sheet'!B9 -> 592367.66 | D12: Current Market Cap (Rs Crore) | E12: ='Data Sheet'!B9 -> 592367.66
A14: EXPLANATION
A15: Ben Graham's Original Formula: Value = EPS x (8.5 + 2G)
A16: Here, EPS is the trailing 12 month EPS, 8.5 is the P/E ratio of a stock with 0% growth and g is the growth rate for the next 7-10 years
A18: Ben Graham's Revised Formula: Value = [EPS x (8.5 + 2G) x 4.4] / Y
A19: Here, 4.4 is what Graham determined to be his minimum required rate of return. At the time of around 1962 when Graham was publicizing his works, the risk free interest rate was 4.4% but to adjust to the present, we divide this number by today’s AAA corporate bond rate, represented by Y in the formula above.
A21: Note: I have used Graham's original formula in the above calculations

Sheet Profit and loss Detailed-BRT 
A1: Profit & Loss Account / Income Statement
A2: ='Basic Sheet'!D2 -> LIFE INSURANCE CORPORATION OF INDIA
A3: Rs Cr | B3: =(Annual[[#This Row],[Column5]]) -> 43555 | C3: =(Annual[[#This Row],[Column6]]) -> 43921 | D3: =(Annual[[#This Row],[Column7]]) -> 44286 | E3: =(Annual[[#This Row],[Column8]]) -> 44651 | F3: =(Annual[[#This Row],[Column9]]) -> 45016 | G3: =(Annual[[#This Row],[Column10]]) -> 45382 | H3: =(Annual[[#This Row],[Column11]]) -> 45747
A4: Sales | B4: =(Annual[[#This Row],[Column5]]) -> 571507.92 | C4: =(Annual[[#This Row],[Column6]]) -> 628042.79 | D4: =(Annual[[#This Row],[Column7]]) -> 690913.83 | E4: =(Annual[[#This Row],[Column8]]) -> 723606.29 | F4: =(Annual[[#This Row],[Column9]]) -> 784627.65 | G4: =(Annual[[#This Row],[Column10]]) -> 845966.37 | H4: =(Annual[[#This Row],[Column11]]) -> 889970.02
A5: % Growth YOY | B5: 0 | C5: =(C4/B4)-1 -> 0.098922286 | D5: =(D4/C4)-1 -> 0.1001063 | E5: =(E4/D4)-1 -> 0.04731771 | F5: =(F4/E4)-1 -> 0.084329505 | G5: =(G4/F4)-1 -> 0.078175578 | H5: =(H4/G4)-1 -> 0.052015838
A6: Expenses | B6: =('Data Sheet'!E21+'Data Sheet'!E22+'Data Sheet'!E23+'Data Sheet'!E24-'Data Sheet'!E19) -> 565587.42 | C6: =('Data Sheet'!F21+'Data Sheet'!F22+'Data Sheet'!F23+'Data Sheet'!F24-'Data Sheet'!F19) -> 634989.32 | D6: =('Data Sheet'!G21+'Data Sheet'!G22+'Data Sheet'!G23+'Data Sheet'!G24-'Data Sheet'!G19) -> 691165.84 | E6: =('Data Sheet'!H21+'Data Sheet'!H22+'Data Sheet'!H23+'Data Sheet'!H24-'Data Sheet'!H19) -> 720279.99 | F6: =('Data Sheet'!I21+'Data Sheet'!I22+'Data Sheet'!I23+'Data Sheet'!I24-'Data Sheet'!I19) -> 750420.45 | G6: =('Data Sheet'!J21+'Data Sheet'!J22+'Data Sheet'!J23+'Data Sheet'!J24-'Data Sheet'!J19) -> 813187.67 | H6: =('Data Sheet'!K21+'Data Sheet'!K22+'Data Sheet'!K23+'Data Sheet'!K24-'Data Sheet'!K19) -> 837270.25
A7: Material Cost (% of Sales) | B7: 0 | C7: 0 | D7: 0 | E7: 0 | F7: 0 | G7: 0 | H7: 0
A8: Power and Fuel | B8: 0 | C8: 0 | D8: 0 | E8: 0 | F8: 0 | G8: 0 | H8: 0
A9: Other Mfr. Exp | B9: =('Data Sheet'!E21/'Data Sheet'!E17) -> 0.91315072 | C9: =('Data Sheet'!F21/'Data Sheet'!F17) -> 0.91606736 | D9: =('Data Sheet'!G21/'Data Sheet'!G17) -> 0.91856618 | E9: =('Data Sheet'!H21/'Data Sheet'!H17) -> 0.95484857 | F9: =('Data Sheet'!I21/'Data Sheet'!I17) -> 0.91307799 | G9: =('Data Sheet'!J21/'Data Sheet'!J17) -> 0.90456502 | H9: =('Data Sheet'!K21/'Data Sheet'!K17) -> 0
A10: Employee Cost | B10: =('Data Sheet'!E22/'Data Sheet'!E17) -> 0.034828109 | C10: =('Data Sheet'!F22/'Data Sheet'!F17) -> 0.040009853 | D10: =('Data Sheet'!G22/'Data Sheet'!G17) -> 0.038770956 | E10: =('Data Sheet'!H22/'Data Sheet'!H17) -> 0.04193811 | F10: =('Data Sheet'!I22/'Data Sheet'!I17) -> 0.051151486 | G10: =('Data Sheet'!J22/'Data Sheet'!J17) -> 0.04683964 | H10: =('Data Sheet'!K22/'Data Sheet'!K17) -> 0.030278188
A11: Selling and Admin Cost | B11: =('Data Sheet'!E23/'Data Sheet'!E17) -> 0.013882642 | C11: =('Data Sheet'!F23/'Data Sheet'!F17) -> 0.013895757 | D11: =('Data Sheet'!G23/'Data Sheet'!G17) -> 0.030587924 | E11: =('Data Sheet'!H23/'Data Sheet'!H17) -> 0.011105791 | F11: =('Data Sheet'!I23/'Data Sheet'!I17) -> 0.0095798944 | G11: =('Data Sheet'!J23/'Data Sheet'!J17) -> 0.0097362617 | H11: =('Data Sheet'!K23/'Data Sheet'!K17) -> 0.00025095227
A12: Operating Profit | B12: =(B4-B6) -> 5920.5 | C12: =(C4-C6) -> -6946.53 | D12: =(D4-D6) -> -252.01 | E12: =(E4-E6) -> 3326.3 | F12: =(F4-F6) -> 34207.2 | G12: =(G4-G6) -> 32778.7 | H12: =(H4-H6) -> 52699.77
A13: Operating Profit Margin | B13: =B12/B4 -> 0.010359436 | C13: =C12/C4 -> -0.0110606 | D13: =D12/D4 -> -0.00036474881 | E13: =E12/E4 -> 0.0045968368 | F13: =F12/F4 -> 0.04359673 | G13: =G12/G4 -> 0.038747049 | H13: =H12/H4 -> 0.059215219
A14: Other Income | B14: ='Data Sheet'!E25 -> 2615.04 | C14: ='Data Sheet'!F25 -> 20869.96 | D14: ='Data Sheet'!G25 -> 12819.51 | E14: ='Data Sheet'!H25 -> 9247.76 | F14: ='Data Sheet'!I25 -> 7799.5 | G14: ='Data Sheet'!J25 -> 14828.66 | H14: ='Data Sheet'!K25 -> 3567.21
A15: Other Income as % of Sales | B15: =B14/B4 -> 0.0045756846 | C15: =C14/C4 -> 0.033230156 | D15: =D14/D4 -> 0.018554427 | E15: =E14/E4 -> 0.012780099 | F15: =F14/F4 -> 0.0099403838 | G15: =G14/G4 -> 0.017528664 | H15: =H14/H4 -> 0.0040082361
A16: Depreciation | B16: =('Data Sheet'!E26) -> 336.41 | C16: =('Data Sheet'!F26) -> 379.36 | D16: =('Data Sheet'!G26) -> 416.63 | E16: =('Data Sheet'!H26) -> 436.19 | F16: =('Data Sheet'!I26) -> 466.38 | G16: =('Data Sheet'!J26) -> 465.94 | H16: 0
A17: Interest | B17: 0 | C17: 0 | D17: 0 | E17: 0 | F17: =('Data Sheet'!I27) -> 77.43 | G17: =('Data Sheet'!J27) -> 127.88 | H17: 0
A18: Interest Coverage(Times) | B18: 0 | C18: 0 | D18: 0 | E18: 0 | F18: =(F17+F19)/F17 -> 536.4887 | G18: =(G17+G19)/G17 -> 368.63794 | H18: 0
A19: Profit before tax (PBT) | B19: ='Data Sheet'!E28 -> 8199.13 | C19: ='Data Sheet'!F28 -> 13544.07 | D19: ='Data Sheet'!G28 -> 12150.87 | E19: ='Data Sheet'!H28 -> 12137.87 | F19: ='Data Sheet'!I28 -> 41462.89 | G19: ='Data Sheet'!J28 -> 47013.54 | H19: ='Data Sheet'!K28 -> 56266.98 | J19: 0.35871774 | K19: 0.31673378
A20: % Growth YOY | B20: 0 | C20: =(C19/B19)-1 -> 0.65189112 | D20: =(D19/C19)-1 -> -0.10286421 | E20: =(E19/D19)-1 -> -0.0010698822 | F20: =(F19/E19)-1 -> 2.4159939 | G20: =(G19/F19)-1 -> 0.13387031 | H20: =(H19/G19)-1 -> 0.196825
A21: PBT Margin | B21: =B19/B4 -> 0.014346485 | C21: =C19/C4 -> 0.021565521 | D21: =D19/D4 -> 0.017586665 | E21: =E19/E4 -> 0.016774136 | F21: =F19/F4 -> 0.052844034 | G21: =G19/G4 -> 0.055573769 | H21: =H19/H4 -> 0.063223456
A22: Tax | B22: ='Data Sheet'!E29 -> 5571.76 | C22: ='Data Sheet'!F29 -> 10833.6 | D22: ='Data Sheet'!G29 -> 9176.73 | E22: ='Data Sheet'!H29 -> 8013.17 | F22: ='Data Sheet'!I29 -> 5466.25 | G22: ='Data Sheet'!J29 -> 6097.69 | H22: ='Data Sheet'!K29 -> 7946.65
A23: Net profit | B23: ='Data Sheet'!E30 -> 2627.38 | C23: ='Data Sheet'!F30 -> 2710.48 | D23: ='Data Sheet'!G30 -> 2974.14 | E23: ='Data Sheet'!H30 -> 4124.71 | F23: ='Data Sheet'!I30 -> 35996.65 | G23: ='Data Sheet'!J30 -> 40915.85 | H23: ='Data Sheet'!K30 -> 48320.33 | J23: 0.74644011
A24: % Growth YOY | B24: 0 | C24: =(C23/B23)-1 -> 0.031628466 | D24: =(D23/C23)-1 -> 0.097274284 | E24: =(E23/D23)-1 -> 0.38685805 | F24: =(F23/E23)-1 -> 7.7270741 | G24: =(G23/F23)-1 -> 0.13665716 | H24: =(H23/G23)-1 -> 0.1809685
A25: Net Profit Margin | B25: 0.0045972591 | C25: =(C23/B23)-1 -> 0.031628466 | D25: 0.0043046468 | F25: =F23/F4 -> 0.045877366 | G25: =G23/G4 -> 0.048365812 | H25: =H23/H4 -> 0.054294335
A26: EPS | B26: =(B23/'Data Sheet'!E93) -> 4.153962 | C26: =(C23/'Data Sheet'!F93) -> 4.2853454 | D26: =(D23/'Data Sheet'!G93) -> 4.7021993 | E26: =(E23/'Data Sheet'!H93) -> 6.5212806 | F26: =(F23/'Data Sheet'!I93) -> 56.9117 | G26: =(G23/'Data Sheet'!J93) -> 64.689091 | H26: =(H23/'Data Sheet'!K93) -> 76.395779 | I26: 0.1031197 | J26: 0.51585743
A27: % Growth YOY | B27: 0 | C27: =(C26/B26)-1 -> 0.031628466 | D27: =(D26/C26)-1 -> 0.097274284 | E27: =(E26/D26)-1 -> 0.38685755 | F27: =(F26/E26)-1 -> 7.7270741 | G27: =(G26/F26)-1 -> 0.13665716 | H27: =(H26/G26)-1 -> 0.1809685
A28: Price to earning (P/E) | B28: 0 | C28: 0 | D28: 0 | E28: 0 | F28: =F29/F26 -> 9.3891063 | G28: =G29/G26 -> 14.162357 | H28: =H29/H26 -> 10.463929
A29: Price | B29: 0 | C29: 0 | D29: 0 | E29: 0 | F29: ='Data Sheet'!I90 -> 534.35 | G29: ='Data Sheet'!J90 -> 916.15 | H29: ='Data Sheet'!K90 -> 799.4
A30: Dividend | B30: ='Data Sheet'!E31 -> 42 | C30: ='Data Sheet'!F31 -> 42.7 | D30: ='Data Sheet'!G31 -> 0 | E30: ='Data Sheet'!H31 -> 948.75 | F30: ='Data Sheet'!I31 -> 1897.5 | G30: ='Data Sheet'!J31 -> 6325 | H30: ='Data Sheet'!K31 -> 7590
A31: Dividend Payout | B31: =B30/B23 -> 0.015985506 | C31: =C30/C23 -> 0.015753667 | D31: =D30/D23 -> 0 | E31: =E30/E23 -> 0.23001617 | F31: =F30/F23 -> 0.052713239 | G31: =G30/G23 -> 0.15458557 | H31: =H30/H23 -> 0.15707674
A32: Market Cap | B32: 0 | C32: 0 | D32: 0 | E32: 0 | F32: =F29*'Data Sheet'!I93 -> 337976.38 | G32: =G29*'Data Sheet'!J93 -> 579464.88 | H32: =H29*'Data Sheet'!K93 -> 505620.5 | I32: Delta MCAP | J32: =H32-F32 -> 167644.12
A33: Retained Earnings | B33: =B23-B30 -> 2585.38 | C33: =C23-C30 -> 2667.78 | D33: =D23-D30 -> 2974.14 | E33: =E23-E30 -> 3175.96 | F33: =F23-F30 -> 34099.15 | G33: =G23-G30 -> 34590.85 | H33: =H23-H30 -> 40730.33 | I33: Accumulated RE | J33: =(F33+G33+H33) -> 109420.33
A34: Buffett's $1 Test | B34: =J32/J33 -> 1.5321113 | J34: =J32/J33 -> 1.5321113

Sheet CashFlow consolidated
A1: Dates | B1: Mar 2016 | C1: Mar 2017 | D1: Mar 2018 | E1: Mar 2019 | F1: Mar 2020 | G1: Mar 2021 | H1: Mar 2022 | I1: Mar 2023 | J1: Mar 2024 | K1: Mar 2025
A2: Cash from Operating Activity | E2: 13273.814 | F2: 54366.921 | G2: 80602.038 | H2: -3782.5358 | I2: 54518.51 | J2: 26121.65 | K2: -9144.77
A3: Profit Before Tax | K3: 492388.43
A4: Adjustments | E4: 36110.555 | F4: 70168.492 | G4: 53303.261 | H4: 5611.8038 | I4: 50964.87 | J4: 23189.66 | K4: -501533.2
A5: OCF Before Working Capital | E5: 36110.555 | F5: 70168.492 | G5: 53303.261 | H5: 5611.8038 | I5: 50964.87 | J5: 23189.66 | K5: -9144.77
A6: Working Capital Changes | E6: -3213.359 | F6: -3458.719 | G6: 18536.061 | H6: 713.9274 | I6: 170.38 | J6: -347.42
A7: Taxes Paid | E7: -19623.382 | F7: -12342.852 | G7: 8762.7165 | H7: -10108.267 | I7: 3383.26 | J7: 3279.41 | K7: 0
A8: Cash from Investing Activity | E8: 8764.5 | F8: -41809.092 | G8: 148792.31 | H8: 12098.798 | I8: -54471.53 | J8: -25400.02 | K8: 40423.43
A9: Net Fixed Assets Purchased | E9: -1992.365 | F9: -920.335 | G9: 6162.9275 | H9: -96.6536 | I9: -542.11 | J9: -712.72 | K9: -714.79
A10: Fixed Assets Purchased | E10: -2545.804 | F10: -1120.26 | G10: -1076.0655 | H10: -716.9387 | I10: -886.47 | J10: -767.77 | K10: -776.73
A11: Fixed Assets Sold | E11: 553.439 | F11: 199.925 | G11: 7238.993 | H11: 620.2851 | I11: 344.36 | J11: 55.05 | K11: 61.94
A12: Investment Purchased | E12: -316629.26 | F12: -426192.62 | G12: -499555.45 | H12: -427781.15 | I12: -543739.38 | J12: -576036.89 | K12: -566852.13
A13: Investment Sold | E13: 133823.64 | F13: 152515.81 | G13: 274807.32 | H13: 190388.11 | I13: 224908.06 | J13: 261903.87 | K13: 307792.15
A14: Interest Recieved | E14: 199144.34 | F14: 231230.59 | G14: 248888.39 | H14: 250559.75 | I14: 268931.48 | J14: 293173.52 | K14: 315107.76
A15: Dividends Recieved
A16: Subsidiary Investments
A17: Cash from Financing Activity | E17: -13699.579 | F17: -18663.744 | G17: -256125.47 | I17: -948.59 | J17: -4427.2 | K17: -3794.28
A18: Proceeds From Shares
A19: Net Long Term Borrowings | E19: 0 | F19: 0 | G19: 0 | H19: 0 | I19: 0 | J19: 0 | K19: 0
A20: Proceeds From Borrowings
A21: Repayment From Borrowings
A22: Interest Paid | F22: -2676.748 | G22: -2715.5344 | I22: -948.59 | J22: -4427.2 | K22: -3794.28
A23: Dividend Paid
A24: Net Cash Flow | E24: 8338.735 | F24: -6105.915 | G24: -26731.118 | H24: 8316.2619 | I24: -901.61 | J24: -3705.57 | K24: 27484.38
A25: Opening Cash & Cash Equivalents | E25: 58695.453 | F25: 67905.954 | G25: 63194.337 | H25: 36117.679 | I25: 44866.05 | J25: 45588.14 | K25: 42013.83
A26: Effect of FX | E26: 871.766 | F26: 1394.297 | G26: -345.5402 | H26: 432.1063 | I26: 1623.7 | J26: 131.26 | K26: 408.27
A27: Closing Cash & Cash Equivalents | E27: 67905.954 | F27: 63194.336 | G27: 36117.679 | H27: 44866.047 | I27: 45588.14 | J27: 42013.83 | K27: 69906.48
A28: Net Capex (est) | E28: 1992.365 | F28: 920.335 | G28: -6162.9275 | H28: 96.6536 | I28: 542.11 | J28: 712.72 | K28: 714.79
A29: Free Cash Flow (est) | E29: 11281.449 | F29: 53446.586 | G29: 86764.966 | H29: -3879.1894 | I29: 53976.4 | J29: 25408.93 | K29: -9859.56

Sheet Basic Sheet
A1: Parameters | D1: Details
A2: Company | D2: LIFE INSURANCE CORPORATION OF INDIA
A3: Current Stock Price (Rs) | D3: ='Data Sheet'!B8 -> 936.55
A4: Face Value (Rs) | D4: =('Data Sheet'!B7) -> 10
A5: No. of Shares (Crore) | D5: =('Data Sheet'!B6) -> 632.49977
A6: Market Capitalization (Rs Crore) | D6: =('Data Sheet'!B9) -> 592367.66
A7: Discount Rate | D7: 0.055
A9: Key Financials - Trend
A10: Parameters
A11: Sales Growth (7-Year CAGR) | D11: =('Profit & Loss'!K4/'Profit & Loss'!E4)^(1/7)-1 -> 0.065317393
A12: Profit Before Tax Growth (7-Year CAGR) | D12: =('Data Sheet'!K28/'Data Sheet'!E28)^(1/7)-1 -> 0.31673378
A13: Net Profit Growth (7-Year CAGR) | D13: =('Profit & Loss'!K12/'Profit & Loss'!E12)^(1/7)-1 -> 0.51585668
A14: Average Debt/Equity (5-Years, x) | D14: =AVERAGE('Balance Sheet'!G25:K25) -> 0.00013093548
A15: Average Return on Equity (5-Years) | D15: =AVERAGE('Balance Sheet'!G23:K23) -> 0.4897371
A16: Average P/E (4-Years, x) | D16: =AVERAGE('Profit & Loss'!I14:L14) -> 11.568643
A17: Latest P/E (x) | D17: =D3/'Profit & Loss'!L13 -> 12.259181

Sheet Dhandho model
A1: LIFE INSURANCE CORPORATION OF INDIA | J1: LIFE INSURANCE CORPORATION OF INDIA
A2: Dhandho IV - Lower Range | J2: Dhandho IV - Higher Range
A3: YEAR | C3: FCF(Rs Cr) | D3: PV of FCF(RS Cr) | E3: Annual FCF Growth | J3: YEAR | L3: FCF(Rs Cr) | M3: PV of FCF(RS Cr) | N3: Annual FCF Growth
A4: 0 | B4: Excess Cash (Latest) | D4: ='Balance Sheet'!K19 -> 69884.66 | E4: Year 1-3 | F4: 0.15 | J4: 0 | K4: Excess Cash (Latest) | M4: ='Balance Sheet'!K19 -> 69884.66 | N4: Year 1-3 | O4: 0.25
A5: 1 | B5: FY26 | C5: ='Cash Flow'!$K$7*(1+'Dhandho model'!$F$4)^'Dhandho model'!A5 -> 31607.037 | D5: =C5/(1+$F$7)^A5 -> 29959.277 | E5: Year4-6 | F5: 0.1 | J5: 1 | K5: FY26 | L5: ='Cash Flow'!$K$14*(1+'Dhandho model'!$O$4)^'Dhandho model'!J5 -> 38102.886 | M5: =L5/(1+$O$7)^J5 -> 36116.48 | N5: Year4-6 | O5: 0.2
A6: 2 | B6: FY27 | C6: ='Cash Flow'!$K$7*(1+'Dhandho model'!$F$4)^'Dhandho model'!A6 -> 36348.093 | D6: =C6/(1+$F$7)^A6 -> 32657.032 | E6: Year 7-10 | F6: 0.05 | J6: 2 | K6: FY27 | L6: ='Cash Flow'!$K$14*(1+'Dhandho model'!$O$4)^'Dhandho model'!J6 -> 47628.607 | M6: =L6/(1+$O$7)^J6 -> 42792.037 | N6: Year 7-10 | O6: 0.15
A7: 3 | B7: FY28 | C7: ='Cash Flow'!$K$7*(1+'Dhandho model'!$F$4)^'Dhandho model'!A7 -> 41800.306 | D7: =C7/(1+$F$7)^A7 -> 35597.712 | E7: Discount Rate | F7: 0.055 | J7: 3 | K7: FY28 | L7: ='Cash Flow'!$K$14*(1+'Dhandho model'!$O$4)^'Dhandho model'!J7 -> 59535.759 | M7: =L7/(1+$O$7)^J7 -> 50701.466 | N7: Discount Rate | O7: 0.055
A8: 4 | B8: FY29 | C8: =C7*(1+$F$5) -> 45980.337 | D8: =C8/(1+$F$7)^A8 -> 37116.098 | J8: 4 | K8: FY29 | L8: =L7*(1+$O$5) -> 71442.911 | M8: =L8/(1+$O$7)^J8 -> 57669.914
A9: 5 | B9: FY30 | C9: =C8*(1+$F$5) -> 50578.371 | D9: =C9/(1+$F$7)^A9 -> 38699.249 | J9: 5 | K9: FY30 | L9: =L8*(1+$O$5) -> 85731.493 | M9: =L9/(1+$O$7)^J9 -> 65596.111
A10: 6 | B10: FY31 | C10: =C9*(1+$F$5) -> 55636.208 | D10: =C10/(1+$F$7)^A10 -> 40349.928 | J10: 6 | K10: FY31 | L10: =L9*(1+$O$5) -> 102877.79 | M10: =L10/(1+$O$7)^J10 -> 74611.69
A11: 7 | B11: FY32 | C11: =C10*(1+$F$6) -> 58418.018 | D11: =C11/(1+$F$7)^A11 -> 40158.696 | J11: 7 | K11: FY32 | L11: =L10*(1+$O$6) -> 118309.46 | M11: =L11/(1+$O$7)^J11 -> 81330.278
A12: 8 | B12: FY33 | C12: =C11*(1+$F$6) -> 61338.919 | D12: =C12/(1+$F$7)^A12 -> 39968.37 | J12: 8 | K12: FY33 | L12: =L11*(1+$O$6) -> 136055.88 | M12: =L12/(1+$O$7)^J12 -> 88653.858
A13: 9 | B13: FY34 | C13: =C12*(1+$F$6) -> 64405.865 | D13: =C13/(1+$F$7)^A13 -> 39778.947 | J13: 9 | K13: FY34 | L13: =L12*(1+$O$6) -> 156464.26 | M13: =L13/(1+$O$7)^J13 -> 96636.907
A14: 10 | B14: FY35 | C14: =C13*(1+$F$6) -> 67626.158 | D14: =C14/(1+$F$7)^A14 -> 39590.421 | J14: 10 | K14: FY35 | L14: =L13*(1+$O$6) -> 179933.9 | M14: =L14/(1+$O$7)^J14 -> 105338.81
A15: 10 | C15: =C14*15 -> 1014392.4 | D15: =D14*15 -> 593856.32 | J15: 10 | L15: =L14*25 -> 4498347.5 | M15: =L15/(1+$O$7)^J15 -> 2633470.2
C17: Intrensic Value(MCAP) | D17: =SUM(D4:D15) -> 1037616.7 | L17: Intrensic Value(MCAP) | M17: =SUM(M4:M15) -> 3402802.4
C18: Discounted Price | D18: =D17/'Data Sheet'!B6 -> 1640.5013 | L18: Discounted Price | M18: =M17/'Data Sheet'!B6 -> 5379.9267
C19: Current Mkt Cap | D19: ='Data Sheet'!B9 -> 592367.66 | L19: Current Mkt Cap | M19: ='Data Sheet'!B9 -> 592367.66
C20: Premium/(Discount) to IV | D20: =D19/D17-1 -> -0.42910744 | L20: Premium (Discount) to IV | M20: =M19/M17-1 -> -0.8259177

Sheet FBTA - TMV - CMMM
B1: TIME MACHINE VALUATION OF AS ON July'2025
B2: LIFE INSURANCE CORPORATION OF INDIA
B3: BACKWARD THINKING APPROACH | M3: FORWARD THINKING APPROACH
B4: ASSUMPTIONS | D4: TERMINAL VALUE | E4: = | F4: LAST YEAR EARNING/(k-g) | M4: ASSUMPTIONS
B5: DISCOUNT RATE (k) | C5: 0.055 | M5: DISCOUNT RATE (k) | N5: 0.055 | P5: ASSUMED GROWTH RATE
B6: TERMINAL GROWTH RATE (g)(ANNUAL) | C6: 0.02 | E6: ACTUAL GROWTH RATE(PBT) | F6: =('Profit & Loss'!K10/'Profit & Loss'!E10)^(1/7)-1 -> 0.31673378 | M6: TERMINAL GROWTH RATE (g)(ANNUAL) | N6: 0.02 | P6: ACTUAL GROWTH RATE | Q6: =('Profit & Loss'!K10/'Profit & Loss'!E10)^(1/7)-1 -> 0.31673378
B8: DECCRIPTION | C8: PBT | D8: PV FACTOR | E8: PRESENT VALUE (IN CR) | F8: EPS | G8: PE | M8: DECCRIPTION | N8: PBT | O8: PV FACTOR | P8: PRESENT VALUE (IN CR) | Q8: =F6/2 -> 0.15836689
A9: 1 | B9: EARNINGS FOR FY 18-19 | C9: ='Profit & Loss'!E10 -> 8199.13 | D9: =1/(1+$C$5)^A9 -> 0.9478673 | E9: =C9*D9 -> 7771.6872 | F9: =C9/E20 -> 12.963056 | G9: =E22/F9 -> 69.736642 | L9: 1 | M9: EARNINGS FOR FY 25-26 | N9: =$C$15*(1+$Q$8)^L9 -> 65177.807 | O9: =1/(1+$N$5)^L9 -> 0.9478673 | P9: =N9*O9 -> 61779.911
A10: 2 | B10: EARNINGS FOR FY 19-20 | C10: =Annual[[#This Row],[Column6]] -> 13544.07 | D10: =1/(1+$C$5)^A10 -> 0.89845242 | E10: =C10*D10 -> 12168.702 | L10: 2 | M10: EARNINGS FOR FY 26-27 | N10: =$C$15*(1+$Q$8)^L10 -> 75499.813 | O10: =1/(1+$N$5)^L10 -> 0.89845242 | P10: =N10*O10 -> 67832.989
A11: 3 | B11: EARNINGS FOR FY 20-21 | C11: ='Profit & Loss'!G10 -> 12150.87 | D11: =1/(1+$C$5)^A11 -> 0.85161366 | E11: =C11*D11 -> 10347.847 | L11: 3 | M11: EARNINGS FOR FY 27-28 | N11: =$C$15*(1+$Q$8)^L11 -> 87456.483 | O11: =1/(1+$N$5)^L11 -> 0.85161366 | P11: =N11*O11 -> 74479.136
A12: 4 | B12: EARNINGS FOR FY 21-22 | C12: ='Profit & Loss'!H10 -> 12137.87 | D12: =1/(1+$C$5)^A12 -> 0.80721674 | E12: =C12*D12 -> 9797.8919 | L12: 4 | M12: EARNINGS FOR FY 28-29 | N12: =$C$15*(1+$Q$8)^L12 -> 101306.69 | O12: =1/(1+$N$5)^L12 -> 0.80721674 | P12: =N12*O12 -> 81776.46
A13: 5 | B13: EARNINGS FOR FY 22-23 | C13: ='Profit & Loss'!I10 -> 41462.89 | D13: =1/(1+$C$5)^A13 -> 0.76513435 | E13: =C13*D13 -> 31724.682 | L13: 5 | M13: EARNINGS FOR FY 29-30 | N13: =$C$15*(1+$Q$8)^L13 -> 117350.32 | O13: =1/(1+$N$5)^L13 -> 0.76513435 | P13: =N13*O13 -> 89788.762
A14: 6 | B14: EARNINGS FOR FY 23-23 | C14: ='Profit & Loss'!J10 -> 47013.54 | D14: =1/(1+$C$5)^A14 -> 0.72524583 | E14: =C14*D14 -> 34096.374 | L14: 6 | M14: EARNINGS FOR FY 30-31 | N14: =$C$15*(1+$Q$8)^L14 -> 135934.73 | O14: =1/(1+$N$5)^L14 -> 0.72524583 | P14: =N14*O14 -> 98586.093
A15: 7 | B15: EARNINGS FOR FY 24-25 | C15: ='Profit & Loss'!K10 -> 56266.98 | D15: =1/(1+$C$5)^A15 -> 0.68743681 | E15: =C15*D15 -> 38679.993 | L15: 7 | M15: EARNINGS FOR FY 31-32 | N15: =$C$15*(1+$Q$8)^L15 -> 157462.29 | O15: =1/(1+$N$5)^L15 -> 0.68743681 | P15: =N15*O15 -> 108245.37
B16: VALUE OF EXPLICIT FORECAST PERIOD | C16: =SUM(C9:C15) -> 190775.35 | E16: =SUM(E9:E15) -> 144587.18 | L16: 8 | M16: EARNINGS FOR FY 32-33 | N16: =$C$15*(1+$Q$8)^L16 -> 182399.1 | O16: =1/(1+$N$5)^L16 -> 0.65159887 | P16: =N16*O16 -> 118851.05
B17: TERMINAL VALUE | C17: =C15/(C5-C6) -> 1607628 | D17: 0.6874 | E17: =C17*D17 -> 1105083.5 | L17: 9 | M17: EARNINGS FOR FY 33-34 | N17: =$C$15*(1+$Q$8)^L17 -> 211285.07 | O17: =1/(1+$N$5)^L17 -> 0.61762926 | P17: =N17*O17 -> 130495.84 | Q17: ]
B18: FAIR VALUE MCAP | C18: =SUM(C16:C17) -> 1798403.4 | E18: =E16+E17 -> 1249670.7 | F18: =C15/E20 -> 88.959684 | G18: =E22/F18 -> 10.161907 | L18: 10 | M18: EARNINGS FOR FY 34-35 | N18: =$C$15*(1+$Q$8)^L18 -> 244745.63 | O18: =1/(1+$N$5)^L18 -> 0.58543058 | P18: =N18*O18 -> 143281.58
B19: FACE VALUE | E19: ='Data Sheet'!B7 -> 10 | M19: VALUE OF EXPLICIT FORECAST PERIOD | N19: =SUM(N9:N18) -> 1378617.9 | P19: =SUM(P9:P18) -> 975117.19
B20: No. of O/S shares | E20: ='Data Sheet'!B6 -> 632.49977 | M20: TERMINAL VALUE | N20: =N18/(N5-N6) -> 6992732.4 | O20: 0.5854 | P20: =N20*O20 -> 4093545.6
B21: SHARE CAPITAL IN 2022 | E21: =E20*E19 -> 6324.9977 | M21: FAIR VALUE MCAP | N21: =SUM(N19:N20) -> 8371350.4 | P21: =P19+P20 -> 5068662.8
B22: PRICE IN MAY 2022 | E22: 904 | M22: FACE VALUE | P22: ='Data Sheet'!B7 -> 10
B23: MCAP IN MAY 2022 | E23: =E22*E20 -> 571779.79 | M23: FULLY DILUTED EQUITY SHARES (IN CRORES) | P23: ='Data Sheet'!B6 -> 632.49977
B24: FAIR VALUE PER SHARE | C24: =(C17+C16)/E20 -> 2843.3265 | E24: =E18/E20 -> 1975.7646 | M24: PRICE in June, 2025 | P24: ='Data Sheet'!B8 -> 936.55
M25: SHARE CAPITAL IN 2025 | P25: =P23*P22 -> 6324.9977
M26: MCAP IN JUNE 2025 | P26: =P24*P23 -> 592367.66
M27: FAIR VALUE PER SHARE ( 10 YEARS FROM NOW) | N27: =N21/P23 -> 13235.341 | O27: Today | P27: =P21/P23 -> 8013.699
M28: EPS (2035) | N28: =N18/P23 -> 386.94976
M29: Forward PE (2035) | N29: =P27/N28 -> 20.709921

Sheet Expected Returns Model
A5: Expected Returns Model
A6: LIFE INSURANCE CORPORATION OF INDIA
A7: Particulars | B7: 43555 | C7: 43921 | D7: 44286 | E7: 44651 | F7: 45016 | G7: 45382 | H7: 45747 | I7: CAGR (3-Yr) | J7: CAGR (7-Yr)
A8: Net Profit (Rs Crore) | B8: ='Profit & Loss'!E12 -> 2627.38 | C8: ='Profit & Loss'!F12 -> 2710.48 | D8: ='Profit & Loss'!G12 -> 2974.14 | E8: ='Profit & Loss'!H12 -> 4124.71 | F8: ='Profit & Loss'!I12 -> 35996.65 | G8: ='Profit & Loss'!J12 -> 40915.85 | H8: ='Profit & Loss'!K12 -> 48320.33 | I8: =(H8/F8)^(1/3)-1 -> 0.1031196 | J8: =(H8/B8)^(1/7)-1 -> 0.51585668
A9: Net Profit Margin | B9: 0.0045972591 | C9: =(C8/B8)-1 -> 0.031628466 | D9: =(D8/C8)-1 -> 0.097274284 | E9: =(E8/D8)-1 -> 0.38685805 | F9: =(F8/E8)-1 -> 7.7270741 | G9: =(G8/F8)-1 -> 0.13665716 | H9: =(H8/G8)-1 -> 0.1809685
A10: Return on Equity | B10: ='Balance Sheet'!E23 -> 3.245001 | C10: ='Balance Sheet'!F23 -> 2.7055289 | D10: ='Balance Sheet'!G23 -> 0.43203849 | E10: ='Balance Sheet'!H23 -> 0.36378461 | F10: ='Balance Sheet'!I23 -> 0.77859432 | G10: ='Balance Sheet'!J23 -> 0.49447006 | H10: ='Balance Sheet'!K23 -> 0.37979801
A11: Calculations (Enter values only in Dark cells) | B11: Higher
A12: Estimated CAGR in Net Profit over next 7 years | B12: =((H8/B8)^(1/7)-1)/2 -> 0.25792834
A13: Estimated Net Profit after 10 years (Rs Cr) | B13: =H8*(1+B12)^10 -> 479389.94
A14: Current P/E (x) | B14: ='Profit & Loss'!K14 -> 10.463929
A15: Exit P/E in the 10th year from now (x, Estimated) | B15: 25
A16: Esti. Market Cap (10th year from now; Rs Cr) | B16: =B13*B15 -> 11984748
A17: Cost of Capital/Discount Rate | B17: 0.055
A18: Discounted MCAP (Rs Cr) | B18: =B16/(1+B17)^10 -> 7016238.2
A19: Discounted Price (Rs) | B19: =B18/'Data Sheet'!B6 -> 11092.871
A20: Current Market Cap (Rs Cr) | B20: ='Data Sheet'!B9 -> 592367.66
B21: Lower
A22: Estimated CAGR in Net Profit over next 5 years | B22: =(H8/F8)^(1/3)-1 -> 0.1031196
A23: Estimated Net Profit after 5 years (Rs Cr) | B23: =H8*(1+B22)^5 -> 78930.145
A24: Current P/E (x) | B24: ='Profit & Loss'!K14 -> 10.463929
A25: Exit P/E in the 5th year from now (x, Estimated) | B25: 20
A26: Esti. Market Cap (5th year from now; Rs Cr) | B26: =B23*B25 -> 1578602.9
A27: Cost of Capital/Discount Rate | B27: 0.055
A28: Discounted MCAP (Rs Cr) | B28: =B26/(1+B27)^5 -> 1207843.3
A29: Discounted Price (Rs) | B29: =B28/'Data Sheet'!B6 -> 1909.6344
A30: Current Market Cap (Rs Cr) | B30: ='Data Sheet'!B9 -> 592367.66

Sheet Data Sheet
A1: COMPANY NAME | B1: LIFE INSURANCE CORPORATION OF INDIA | E1: =IF(B2<>B3, "A NEW VERSION OF THE WORKSHEET IS AVAILABLE", "")
A2: LATEST VERSION | B2: 2.1 | E2: PLEASE DO NOT MAKE ANY CHANGES TO THIS SHEET
A3: CURRENT VERSION | B3: 2.1
A5: META
A6: Number of shares | B6: =IF(B9>0, B9/B8, 0) -> 632.49977
A7: Face Value | B7: 10
A8: Current Price | B8: 936.55
A9: Market Capitalization | B9: 592367.66
A15: PROFIT & LOSS
A16: Report Date | E16: 43555 | F16: 43921 | G16: 44286 | H16: 44651 | I16: 45016 | J16: 45382 | K16: 45747
A17: Sales | E17: 571507.92 | F17: 628042.79 | G17: 690913.83 | H17: 723606.29 | I17: 784627.65 | J17: 845966.37 | K17: 889970.02
A18: Raw Material Cost
A19: Change in Inventory | E19: 0
A20: Power and Fuel
A21: Other Mfr. Exp | E21: 521872.87 | F21: 575329.5 | G21: 634650.08 | H21: 690934.43 | I21: 716426.24 | J21: 765231.59
A22: Employee Cost | E22: 19904.54 | F22: 25127.9 | G22: 26787.39 | H22: 30346.68 | I22: 40134.87 | J22: 39624.76 | K22: 26946.68
A23: Selling and admin | E23: 7934.04 | F23: 8727.13 | G23: 21133.62 | H23: 8036.22 | I23: 7516.65 | J23: 8236.55 | K23: 223.34
A24: Other Expenses | E24: 15875.97 | F24: 25804.79 | G24: 8594.75 | H24: -9037.34 | I24: -13657.31 | J24: 94.77 | K24: 810100.23
A25: Other Income | E25: 2615.04 | F25: 20869.96 | G25: 12819.51 | H25: 9247.76 | I25: 7799.5 | J25: 14828.66 | K25: 3567.21
A26: Depreciation | E26: 336.41 | F26: 379.36 | G26: 416.63 | H26: 436.19 | I26: 466.38 | J26: 465.94
A27: Interest | I27: 77.43 | J27: 127.88
A28: Profit before tax | E28: 8199.13 | F28: 13544.07 | G28: 12150.87 | H28: 12137.87 | I28: 41462.89 | J28: 47013.54 | K28: 56266.98
A29: Tax | E29: 5571.76 | F29: 10833.6 | G29: 9176.73 | H29: 8013.17 | I29: 5466.25 | J29: 6097.69 | K29: 7946.65
A30: Net profit | E30: 2627.38 | F30: 2710.48 | G30: 2974.14 | H30: 4124.71 | I30: 35996.65 | J30: 40915.85 | K30: 48320.33
A31: Dividend Amount | E31: 42 | F31: 42.7 | H31: 948.75 | I31: 1897.5 | J31: 6325 | K31: 7590
A40: Quarters
A41: Report Date | B41: 44926 | C41: 45016 | D41: 45107 | E41: 45199 | F41: 45291 | G41: 45382 | H41: 45473 | I41: 45565 | J41: 45657 | K41: 45747
A42: Sales | B42: 197714.39 | C42: 201231.11 | D42: 190163.06 | E42: 203032.88 | F42: 214053.82 | G42: 238716.59 | H42: 211952.09 | I42: 231132.12 | J42: 203751.32 | K42: 243134.49
A43: Expenses | B43: 194094 | C43: 189692.39 | D43: 180169.03 | E43: 194558.2 | F43: 204814.94 | G43: 237152.44 | H43: 202179.5 | I43: 224544.06 | J43: 191817.52 | K43: 221620.59
A44: Other Income | B44: 270.5 | C44: 612.26 | D44: 117.19 | E44: 288.37 | F44: 206.32 | G44: 14248.72 | H44: 1001.06 | I44: 794.29 | J44: 818.02 | K44: 953.84
A45: Depreciation
A46: Interest
A47: Profit before tax | B47: 3890.89 | C47: 12150.98 | D47: 10111.22 | E47: 8763.05 | F47: 9445.2 | G47: 15812.87 | H47: 10773.65 | I47: 7382.35 | J47: 12751.82 | K47: 22467.74
A48: Tax | B48: -2457.83 | C48: 990.84 | D48: 1461.4 | E48: 1181.3 | F48: 1423.72 | G48: 1971.28 | H48: 1629.21 | I48: 1145.2 | J48: 1743.17 | K48: 3429.07
A49: Net profit | B49: 7310.77 | C49: 13190.79 | D49: 9634.98 | E49: 8030.28 | F49: 9468.99 | G49: 13841.59 | H49: 10544.33 | I49: 7728.68 | J49: 11008.65 | K49: 19038.67
A50: Operating Profit | B50: 3620.39 | C50: 11538.72 | D50: 9994.03 | E50: 8474.68 | F50: 9238.88 | G50: 1564.15 | H50: 9772.59 | I50: 6588.06 | J50: 11933.8 | K50: 21513.9
A55: BALANCE SHEET
A56: Report Date | E56: 43555 | F56: 43921 | G56: 44286 | H56: 44651 | I56: 45016 | J56: 45382 | K56: 45747
A57: Equity Share Capital | E57: 100 | F57: 100 | G57: 100 | H57: 6325 | I57: 6325 | J57: 6325 | K57: 6325
A58: Reserves | E58: 709.67 | F58: 901.83 | G58: 6783.97 | H58: 5013.33 | I58: 39907.87 | J58: 76421.87 | K58: 120901.39
...

Sheet Quarters
A1: ='Profit & Loss'!A1 -> LIFE INSURANCE CORPORATION OF INDIA | E1: =UPDATE | J1: SCREENER.IN
A3: Narration | B3: ='Data Sheet'!B41 -> 44926 | C3: ='Data Sheet'!C41 -> 45016 | D3: ='Data Sheet'!D41 -> 45107 | E3: ='Data Sheet'!E41 -> 45199 | F3: ='Data Sheet'!F41 -> 45291 | G3: ='Data Sheet'!G41 -> 45382 | H3: ='Data Sheet'!H41 -> 45473 | I3: ='Data Sheet'!I41 -> 45565 | ... K3: ='Data Sheet'!K41 -> 45747
A4: Sales | B4: ='Data Sheet'!B42 -> 197714.39 | C4: ='Data Sheet'!C42 -> 201231.11 | D4: ='Data Sheet'!D42 -> 190163.06 | E4: ='Data Sheet'!E42 -> 203032.88 | F4: ='Data Sheet'!F42 -> 214053.82 | G4: ='Data Sheet'!G42 -> 238716.59 | H4: ='Data Sheet'!H42 -> 211952.09 | I4: ='Data Sheet'!I42 -> 231132.12 | ... K4: ='Data Sheet'!K42 -> 243134.49
A5: Expenses | B5: ='Data Sheet'!B43 -> 194094 | C5: ='Data Sheet'!C43 -> 189692.39 | D5: ='Data Sheet'!D43 -> 180169.03 | E5: ='Data Sheet'!E43 -> 194558.2 | F5: ='Data Sheet'!F43 -> 204814.94 | G5: ='Data Sheet'!G43 -> 237152.44 | H5: ='Data Sheet'!H43 -> 202179.5 | I5: ='Data Sheet'!I43 -> 224544.06 | ... K5: ='Data Sheet'!K43 -> 221620.59
A6: Operating Profit | B6: ='Data Sheet'!B50 -> 3620.39 | C6: ='Data Sheet'!C50 -> 11538.72 | D6: ='Data Sheet'!D50 -> 9994.03 | E6: ='Data Sheet'!E50 -> 8474.68 | F6: ='Data Sheet'!F50 -> 9238.88 | G6: ='Data Sheet'!G50 -> 1564.15 | H6: ='Data Sheet'!H50 -> 9772.59 | I6: ='Data Sheet'!I50 -> 6588.06 | ... K6: ='Data Sheet'!K50 -> 21513.9
A7: Other Income | B7: ='Data Sheet'!B44 -> 270.5 | C7: ='Data Sheet'!C44 -> 612.26 | D7: ='Data Sheet'!D44 -> 117.19 | E7: ='Data Sheet'!E44 -> 288.37 | F7: ='Data Sheet'!F44 -> 206.32 | G7: ='Data Sheet'!G44 -> 14248.72 | H7: ='Data Sheet'!H44 -> 1001.06 | I7: ='Data Sheet'!I44 -> 794.29 | ... K7: ='Data Sheet'!K44 -> 953.84
A8: Depreciation | B8: ='Data Sheet'!B45 -> 0 | C8: ='Data Sheet'!C45 -> 0 | D8: ='Data Sheet'!D45 -> 0 | E8: ='Data Sheet'!E45 -> 0 | F8: ='Data Sheet'!F45 -> 0 | G8: ='Data Sheet'!G45 -> 0 | H8: ='Data Sheet'!H45 -> 0 | I8: ='Data Sheet'!I45 -> 0 | ... K8: ='Data Sheet'!K45 -> 0
A9: Interest | B9: ='Data Sheet'!B46 -> 0 | C9: ='Data Sheet'!C46 -> 0 | D9: ='Data Sheet'!D46 -> 0 | E9: ='Data Sheet'!E46 -> 0 | F9: ='Data Sheet'!F46 -> 0 | G9: ='Data Sheet'!G46 -> 0 | H9: ='Data Sheet'!H46 -> 0 | I9: ='Data Sheet'!I46 -> 0 | ... K9: ='Data Sheet'!K46 -> 0
A10: Profit before tax | B10: ='Data Sheet'!B47 -> 3890.89 | C10: ='Data Sheet'!C47 -> 12150.98 | D10: ='Data Sheet'!D47 -> 10111.22 | E10: ='Data Sheet'!E47 -> 8763.05 | F10: ='Data Sheet'!F47 -> 9445.2 | G10: ='Data Sheet'!G47 -> 15812.87 | H10: ='Data Sheet'!H47 -> 10773.65 | I10: ='Data Sheet'!I47 -> 7382.35 | ... K10: ='Data Sheet'!K47 -> 22467.74
A11: Tax | B11: ='Data Sheet'!B48 -> -2457.83 | C11: ='Data Sheet'!C48 -> 990.84 | D11: ='Data Sheet'!D48 -> 1461.4 | E11: ='Data Sheet'!E48 -> 1181.3 | F11: ='Data Sheet'!F48 -> 1423.72 | G11: ='Data Sheet'!G48 -> 1971.28 | H11: ='Data Sheet'!H48 -> 1629.21 | I11: ='Data Sheet'!I48 -> 1145.2 | ... K11: ='Data Sheet'!K48 -> 3429.07
A12: Net profit | B12: ='Data Sheet'!B49 -> 7310.77 | C12: ='Data Sheet'!C49 -> 13190.79 | D12: ='Data Sheet'!D49 -> 9634.98 | E12: ='Data Sheet'!E49 -> 8030.28 | F12: ='Data Sheet'!F49 -> 9468.99 | G12: ='Data Sheet'!G49 -> 13841.59 | H12: ='Data Sheet'!H49 -> 10544.33 | I12: ='Data Sheet'!I49 -> 7728.68 | ... K12: ='Data Sheet'!K49 -> 19038.67
A14: OPM | B14: =IF(B4>0,B6/B4,"") -> 0.018311211 | C14: =IF(C4>0,C6/C4,"") -> 0.057340637 | D14: =IF(D4>0,D6/D4,"") -> 0.052555055 | E14: =IF(E4>0,E6/E4,"") -> 0.041740431 | F14: =IF(F4>0,F6/F4,"") -> 0.043161482 | G14: =IF(G4>0,G6/G4,"") -> 0.0065523305 | H14: =IF(H4>0,H6/H4,"") -> 0.046107543 | I14: =IF(I4>0,I6/I4,"") -> 0.028503438 | ... K14: =IF(K4>0,K6/K4,"") -> 0.088485595

Sheet Profit & Loss
A1: ='Data Sheet'!B1 -> LIFE INSURANCE CORPORATION OF INDIA | H1: =UPDATE | M1: SCREENER.IN
A3: Narration | B3: ='Data Sheet'!B16 -> 0 | C3: ='Data Sheet'!C16 -> 0 | D3: ='Data Sheet'!D16 -> 0 | E3: ='Data Sheet'!E16 -> 43555 | F3: ='Data Sheet'!F16 -> 43921 | G3: ='Data Sheet'!G16 -> 44286 | H3: ='Data Sheet'!H16 -> 44651 | I3: ='Data Sheet'!I16 -> 45016 | ... K3: ='Data Sheet'!K16 -> 45747 | L3: Trailing | M3: Best Case | N3: Worst Case
A4: Sales | B4: ='Data Sheet'!B17 -> 0 | C4: ='Data Sheet'!C17 -> 0 | D4: ='Data Sheet'!D17 -> 0 | E4: ='Data Sheet'!E17 -> 571507.92 | F4: ='Data Sheet'!F17 -> 628042.79 | G4: ='Data Sheet'!G17 -> 690913.83 | H4: ='Data Sheet'!H17 -> 723606.29 | I4: ='Data Sheet'!I17 -> 784627.65 | ... K4: ='Data Sheet'!K17 -> 889970.02 | L4: =SUM(Quarters!H4:K4) -> 889970.02 | M4: =$K4+M23*K4 -> 953527.14 | N4: =$K4+N23*L4 -> 936262.56
A5: Expenses | B5: =SUM('Data Sheet'!B18,'Data Sheet'!B20:B24, -1*'Data Sheet'!B19) -> 0 | C5: =SUM('Data Sheet'!C18,'Data Sheet'!C20:C24, -1*'Data Sheet'!C19) -> 0 | D5: =SUM('Data Sheet'!D18,'Data Sheet'!D20:D24, -1*'Data Sheet'!D19) -> 0 | E5: =SUM('Data Sheet'!E18,'Data Sheet'!E20:E24, -1*'Data Sheet'!E19) -> 565587.42 | F5: =SUM('Data Sheet'!F18,'Data Sheet'!F20:F24, -1*'Data Sheet'!F19) -> 634989.32 | G5: =SUM('Data Sheet'!G18,'Data Sheet'!G20:G24, -1*'Data Sheet'!G19) -> 691165.84 | H5: =SUM('Data Sheet'!H18,'Data Sheet'!H20:H24, -1*'Data Sheet'!H19) -> 720279.99 | I5: =SUM('Data Sheet'!I18,'Data Sheet'!I20:I24, -1*'Data Sheet'!I19) -> 750420.45 | ... K5: =SUM('Data Sheet'!K18,'Data Sheet'!K20:K24, -1*'Data Sheet'!K19) -> 837270.25 | L5: =SUM(Quarters!H5:K5) -> 840161.67 | M5: =M4-M6 -> 900161.73 | N5: =N4-N6 -> 912752.68
A6: Operating Profit | B6: =B4-B5 -> 0 | C6: =C4-C5 -> 0 | D6: =D4-D5 -> 0 | E6: =E4-E5 -> 5920.5 | F6: =F4-F5 -> -6946.53 | G6: =G4-G5 -> -252.01 | H6: =H4-H5 -> 3326.3 | I6: =I4-I5 -> 34207.2 | ... K6: =K4-K5 -> 52699.77 | L6: =SUM(Quarters!H6:K6) -> 49808.35 | M6: =M4*M24 -> 53365.408 | N6: =N4*N24 -> 23509.879
A7: Other Income | B7: ='Data Sheet'!B25 -> 0 | C7: ='Data Sheet'!C25 -> 0 | D7: ='Data Sheet'!D25 -> 0 | E7: ='Data Sheet'!E25 -> 2615.04 | F7: ='Data Sheet'!F25 -> 20869.96 | G7: ='Data Sheet'!G25 -> 12819.51 | H7: ='Data Sheet'!H25 -> 9247.76 | I7: ='Data Sheet'!I25 -> 7799.5 | ... K7: ='Data Sheet'!K25 -> 3567.21 | L7: =SUM(Quarters!H7:K7) -> 3567.21 | M7: 0 | N7: 0
A8: Depreciation | B8: ='Data Sheet'!B26 -> 0 | C8: ='Data Sheet'!C26 -> 0 | D8: ='Data Sheet'!D26 -> 0 | E8: ='Data Sheet'!E26 -> 336.41 | F8: ='Data Sheet'!F26 -> 379.36 | G8: ='Data Sheet'!G26 -> 416.63 | H8: ='Data Sheet'!H26 -> 436.19 | I8: ='Data Sheet'!I26 -> 466.38 | ... K8: ='Data Sheet'!K26 -> 0 | L8: =SUM(Quarters!H8:K8) -> 0 | M8: =+$L8 -> 0 | N8: =+$L8 -> 0
A9: Interest | B9: ='Data Sheet'!B27 -> 0 | C9: ='Data Sheet'!C27 -> 0 | D9: ='Data Sheet'!D27 -> 0 | E9: ='Data Sheet'!E27 -> 0 | F9: ='Data Sheet'!F27 -> 0 | G9: ='Data Sheet'!G27 -> 0 | H9: ='Data Sheet'!H27 -> 0 | I9: ='Data Sheet'!I27 -> 77.43 | ... K9: ='Data Sheet'!K27 -> 0 | L9: =SUM(Quarters!H9:K9) -> 0 | M9: =+$L9 -> 0 | N9: =+$L9 -> 0
A10: Profit before tax | B10: ='Data Sheet'!B28 -> 0 | C10: ='Data Sheet'!C28 -> 0 | D10: ='Data Sheet'!D28 -> 0 | E10: ='Data Sheet'!E28 -> 8199.13 | F10: ='Data Sheet'!F28 -> 13544.07 | G10: ='Data Sheet'!G28 -> 12150.87 | H10: ='Data Sheet'!H28 -> 12137.87 | I10: ='Data Sheet'!I28 -> 41462.89 | ... K10: ='Data Sheet'!K28 -> 56266.98 | L10: =SUM(Quarters!H10:K10) -> 53375.56 | M10: =M6+M7-SUM(M8:M9) -> 53365.408 | N10: =N6+N7-SUM(N8:N9) -> 23509.879
A11: Tax | B11: ='Data Sheet'!B29 -> 0 | C11: ='Data Sheet'!C29 -> 0 | D11: ='Data Sheet'!D29 -> 0 | E11: ='Data Sheet'!E29 -> 5571.76 | F11: ='Data Sheet'!F29 -> 10833.6 | G11: ='Data Sheet'!G29 -> 9176.73 | H11: ='Data Sheet'!H29 -> 8013.17 | I11: ='Data Sheet'!I29 -> 5466.25 | ... K11: ='Data Sheet'!K29 -> 7946.65 | L11: =SUM(Quarters!H11:K11) -> 7946.65 | M11: =IF($L10>0,$L11/$L10,0) -> 0.14888181 | N11: =IF($L10>0,$L11/$L10,0) -> 0.14888181
A12: Net profit | B12: ='Data Sheet'!B30 -> 0 | C12: ='Data Sheet'!C30 -> 0 | D12: ='Data Sheet'!D30 -> 0 | E12: ='Data Sheet'!E30 -> 2627.38 | F12: ='Data Sheet'!F30 -> 2710.48 | G12: ='Data Sheet'!G30 -> 2974.14 | H12: ='Data Sheet'!H30 -> 4124.71 | I12: ='Data Sheet'!I30 -> 35996.65 | ... K12: ='Data Sheet'!K30 -> 48320.33 | L12: =SUM(Quarters!H12:K12) -> 48320.33 | M12: =M10-M11*M10 -> 45420.27 | N12: =N10-N11*N10 -> 20009.686
A13: EPS | B13: =IF('Data Sheet'!B93>0,B12/'Data Sheet'!B93,0) -> 0 | C13: =IF('Data Sheet'!C93>0,C12/'Data Sheet'!C93,0) -> 0 | D13: =IF('Data Sheet'!D93>0,D12/'Data Sheet'!D93,0) -> 0 | E13: =IF('Data Sheet'!E93>0,E12/'Data Sheet'!E93,0) -> 4.153962 | F13: =IF('Data Sheet'!F93>0,F12/'Data Sheet'!F93,0) -> 4.2853454 | G13: =IF('Data Sheet'!G93>0,G12/'Data Sheet'!G93,0) -> 4.7021993 | H13: =IF('Data Sheet'!H93>0,H12/'Data Sheet'!H93,0) -> 6.5212806 | I13: =IF('Data Sheet'!I93>0,I12/'Data Sheet'!I93,0) -> 56.9117 | ... K13: =IF('Data Sheet'!K93>0,K12/'Data Sheet'!K93,0) -> 76.395779 | L13: =IF('Data Sheet'!$B6>0,'Profit & Loss'!L12/'Data Sheet'!$B6,0) -> 76.395806 | M13: =IF('Data Sheet'!$B6>0,'Profit & Loss'!M12/'Data Sheet'!$B6,0) -> 71.810729 | N13: =IF('Data Sheet'!$B6>0,'Profit & Loss'!N12/'Data Sheet'!$B6,0) -> 31.635878
A14: Price to earning | B14: =IF(B15>0,B15/B13,"") | C14: =IF(C15>0,C15/C13,"") | D14: =IF(D15>0,D15/D13,"") | E14: =IF(E15>0,E15/E13,"") | F14: =IF(F15>0,F15/F13,"") | G14: =IF(G15>0,G15/G13,"") | H14: =IF(H15>0,H15/H13,"") | I14: =IF(I15>0,I15/I13,"") -> 9.3891063 | ... K14: =IF(K15>0,K15/K13,"") -> 10.463929 | L14: =IF(L13>0,L15/L13,0) -> 12.259181 | M14: =M25 -> 12.259181 | N14: =N25 -> 11.568643
A15: Price | B15: ='Data Sheet'!B90 -> 0 | C15: ='Data Sheet'!C90 -> 0 | D15: ='Data Sheet'!D90 -> 0 | E15: ='Data Sheet'!E90 -> 0 | F15: ='Data Sheet'!F90 -> 0 | G15: ='Data Sheet'!G90 -> 0 | H15: ='Data Sheet'!H90 -> 0 | I15: ='Data Sheet'!I90 -> 534.35 | ... K15: ='Data Sheet'!K90 -> 799.4 | L15: ='Data Sheet'!B8 -> 936.55 | M15: =M13*M14 -> 880.34071 | N15: =N13*N14 -> 365.98419
A17: RATIOS:
A18: Dividend Payout | B18: =IF('Data Sheet'!B30>0, 'Data Sheet'!B31/'Data Sheet'!B30, 0) -> 0 | C18: =IF('Data Sheet'!C30>0, 'Data Sheet'!C31/'Data Sheet'!C30, 0) -> 0 | D18: =IF('Data Sheet'!D30>0, 'Data Sheet'!D31/'Data Sheet'!D30, 0) -> 0 | E18: =IF('Data Sheet'!E30>0, 'Data Sheet'!E31/'Data Sheet'!E30, 0) -> 0.015985506 | F18: =IF('Data Sheet'!F30>0, 'Data Sheet'!F31/'Data Sheet'!F30, 0) -> 0.015753667 | G18: =IF('Data Sheet'!G30>0, 'Data Sheet'!G31/'Data Sheet'!G30, 0) -> 0 | H18: =IF('Data Sheet'!H30>0, 'Data Sheet'!H31/'Data Sheet'!H30, 0) -> 0.23001617 | I18: =IF('Data Sheet'!I30>0, 'Data Sheet'!I31/'Data Sheet'!I30, 0) -> 0.052713239 | ... K18: =IF('Data Sheet'!K30>0, 'Data Sheet'!K31/'Data Sheet'!K30, 0) -> 0.15707674
A19: OPM | B19: =IF(B6>0,B6/B4,0) -> 0 | C19: =IF(C6>0,C6/C4,0) -> 0 | D19: =IF(D6>0,D6/D4,0) -> 0 | E19: =IF(E6>0,E6/E4,0) -> 0.010359436 | F19: =IF(F6>0,F6/F4,0) -> 0 | G19: =IF(G6>0,G6/G4,0) -> 0 | H19: =IF(H6>0,H6/H4,0) -> 0.0045968368 | I19: =IF(I6>0,I6/I4,0) -> 0.04359673 | ... L19: =IF(L6>0,L6/L4,0) -> 0.055966323
G22: TRENDS: | H22: 10 YEARS | I22: 7 YEARS | J22: 5 YEARS | K22: 3 YEARS | L22: RECENT | M22: BEST | N22: WORST
G23: Sales Growth | H23: =IF(B4=0,"",POWER($K4/B4,1/9)-1) | I23: =IF(D4=0,"",POWER($K4/D4,1/7)-1) | J23: =IF(F4=0,"",POWER($K4/F4,1/5)-1) -> 0.07220352 | K23: =IF(H4=0,"",POWER($K4/H4, 1/3)-1) -> 0.071414899 | L23: =IF(ISERROR(MAX(IF(J4=0,"",(K4-J4)/J4),IF(K4=0,"",(L4-K4)/K4))),"",MAX(IF(J4=0,"",(K4-J4)/J4),IF(K4=0,"",(L4-K4)/K4))) -> 0.052015838 | M23: =MAX(K23:L23) -> 0.071414899 | N23: =MIN(H23:L23) -> 0.052015838
G24: OPM | H24: =IF(SUM(B4:$K$4)=0,"",SUMPRODUCT(B19:$K$19,B4:$K$4)/SUM(B4:$K$4)) -> 0.025110348 | I24: =IF(SUM(E4:$K$4)=0,"",SUMPRODUCT(E19:$K$19,E4:$K$4)/SUM(E4:$K$4)) -> 0.025110348 | J24: =IF(SUM(G4:$K$4)=0,"",SUMPRODUCT(G19:$K$19,G4:$K$4)/SUM(G4:$K$4)) -> 0.031260315 | K24: =IF(SUM(I4:$K$4)=0, "", SUMPRODUCT(I19:$K$19,I4:$K$4)/SUM(I4:$K$4)) -> 0.047483685 | L24: =L19 -> 0.055966323 | M24: =MAX(K24:L24) -> 0.055966323 | N24: =MIN(H24:L24) -> 0.025110348
A25: Debt/Equity | G25: Price to Earning | H25: =IF(ISERROR(AVERAGEIF(B14:$L14,">0")),"",AVERAGEIF(B14:$L14,">0")) -> 11.568643 | I25: =IF(ISERROR(AVERAGEIF(E14:$L14,">0")),"",AVERAGEIF(E14:$L14,">0")) -> 11.568643 | J25: =IF(ISERROR(AVERAGEIF(G14:$L14,">0")),"",AVERAGEIF(G14:$L14,">0")) -> 11.568643 | K25: =IF(ISERROR(AVERAGEIF(I14:$L14,">0")),"",AVERAGEIF(I14:$L14,">0")) -> 11.568643 | L25: =L14 -> 12.259181 | M25: =MAX(K25:L25) -> 12.259181 | N25: =MIN(H25:L25) -> 11.568643

Sheet Balance Sheet
A1: ='Profit & Loss'!A1 -> LIFE INSURANCE CORPORATION OF INDIA | E1: =UPDATE | J1: SCREENER.IN
A3: Narration | B3: ='Data Sheet'!B56 -> 0 | C3: ='Data Sheet'!C56 -> 0 | D3: ='Data Sheet'!D56 -> 0 | E3: ='Data Sheet'!E56 -> 43555 | F3: ='Data Sheet'!F56 -> 43921 | G3: ='Data Sheet'!G56 -> 44286 | H3: ='Data Sheet'!H56 -> 44651 | I3: ='Data Sheet'!I56 -> 45016 | ... K3: ='Data Sheet'!K56 -> 45747
A4: Equity Share Capital | B4: ='Data Sheet'!B57 -> 0 | C4: ='Data Sheet'!C57 -> 0 | D4: ='Data Sheet'!D57 -> 0 | E4: ='Data Sheet'!E57 -> 100 | F4: ='Data Sheet'!F57 -> 100 | G4: ='Data Sheet'!G57 -> 100 | H4: ='Data Sheet'!H57 -> 6325 | I4: ='Data Sheet'!I57 -> 6325 | ... K4: ='Data Sheet'!K57 -> 6325
A5: Reserves | B5: ='Data Sheet'!B58 -> 0 | C5: ='Data Sheet'!C58 -> 0 | D5: ='Data Sheet'!D58 -> 0 | E5: ='Data Sheet'!E58 -> 709.67 | F5: ='Data Sheet'!F58 -> 901.83 | G5: ='Data Sheet'!G58 -> 6783.97 | H5: ='Data Sheet'!H58 -> 5013.33 | I5: ='Data Sheet'!I58 -> 39907.87 | ... K5: ='Data Sheet'!K58 -> 120901.39
A6: Borrowings | B6: ='Data Sheet'!B59 -> 0 | C6: ='Data Sheet'!C59 -> 0 | D6: ='Data Sheet'!D59 -> 0 | E6: ='Data Sheet'!E59 -> 269400.6 | F6: ='Data Sheet'!F59 -> 253413.6 | G6: ='Data Sheet'!G59 -> 3.67 | H6: ='Data Sheet'!H59 -> 1.29 | I6: ='Data Sheet'!I59 -> 0 | ... K6: ='Data Sheet'!K59 -> 0.99
A7: Other Liabilities | B7: ='Data Sheet'!B60 -> 0 | C7: ='Data Sheet'!C60 -> 0 | D7: ='Data Sheet'!D60 -> 0 | E7: ='Data Sheet'!E60 -> 3157039 | F7: ='Data Sheet'!F60 -> 3245418.6 | G7: ='Data Sheet'!G60 -> 3822636.6 | H7: ='Data Sheet'!H60 -> 4242719.3 | I7: ='Data Sheet'!I60 -> 4532258.5 | ... K7: ='Data Sheet'!K60 -> 5533341.1
